<?xml version="1.0"?>
<robot xmlns:xacro="http://www.ros.org/wiki/xacro">  

<xacro:macro name="cylinder_inertia" params="m r h">
    <inertia  ixx="${m*(3*r*r+h*h)/12}" ixy = "0" ixz = "0"
        iyy="${m*(3*r*r+h*h)/12}" iyz = "0"
        izz="${m*r*r/2}" /> 
</xacro:macro>

<!-- wheel right --> 
<link name="wheel_right_link">
    <collision name="wheel_right_collision">
      <origin rpy="3.14159265 0 0" xyz=" 0 0 0" />
      <geometry>
        <mesh filename="file://$(find tondeuse_description)/sdf/mesh/roue.dae" scale="0.001 0.001 0.001"/>
      </geometry>
    </collision>
    <visual name="wheel_right_visual">
      <origin rpy="3.14159265 0 0" xyz=" 0 0 0" />
      <geometry>
          <mesh filename="file://$(find tondeuse_description)/sdf/mesh/roue.dae" scale="0.001 0.001 0.001"/>
      </geometry>
    </visual>
    <inertial>
      <origin rpy="3.14159265 0 0" xyz=" 0 0 0" />
      <mass value="0.01" />
      <xacro:cylinder_inertia m="0.01" r="0.110" h="0.05"/>
    </inertial>

</link>

<joint name="wheel_right_joint" type="continuous">
    <origin rpy="-1.570796 0 0" xyz="0 -0.195 0" />
    <child link="wheel_right_link"/>
    <parent link="base_link"/>
    <axis xyz="0 0 1"/>
</joint>

  <!-- wheel_left_link -->
<link name="wheel_left_link">
    <collision name="wheel_left_collision">
      <origin rpy="0 0 0" xyz="0 0 0" />
      <geometry>
        <mesh filename="file://$(find tondeuse_description)/sdf/mesh/roue.dae" scale="0.001 0.001 0.001"/>
      </geometry>
    </collision>
    <visual name="wheel_left_visual">
      <origin rpy="0 0 0" xyz="0 0 0" />
      <geometry>
        <mesh filename="file://$(find tondeuse_description)/sdf/mesh/roue.dae" scale="0.001 0.001 0.001"/>
      </geometry>
    </visual>
    <inertial>
      <origin rpy="0 0 0" xyz="0 0 0" />
      <mass value="0.01" />
      <xacro:cylinder_inertia m="0.01" r="0.110" h="0.05"/>
    </inertial>
</link>
<joint name="wheel_left_joint" type="continuous">
    <origin rpy="-1.570796 0 0" xyz="0 0.195 0" />
    <child link="wheel_left_link"/>
    <parent link="base_link"/>
    <axis xyz="0 0 1 "/>
</joint>

  </robot>
